Workbook

Sheet Sheet4
A3: 外尺寸规格 | B3: 计数项:外尺寸规格
A4: (空白)
A5: 38×30×8(红) | B5: 1
A6: 38×30×8 | B6: 1
A7: 38×28×8 | B7: 1
A8: 38×28×6 | B8: 1
A9: 38×27×5 | B9: 1
A10: 38×27×2 | B10: 1
A11: 38×25×5(黑) | B11: 1
A12: 38×25×5 | B12: 1
A13: 38×25×1.65(台) | B13: 1
A14: 38×24×8 | B14: 1
A15: 38×23×5(黑) | B15: 1
A16: 38×21×6 | B16: 1
... A2415: 总计 | B2415: 2410

Sheet 长方形
D1: 26年3月仓库长方形及其他颜色飞机盒台帐 | U1: S
C3: 序号 | D3: 外尺寸规格 | E3: 内尺寸规格 | F3: 货位 | G3: 上月在库 | AO3: 出库记录
H4: 剩余库存 | I4: 入库合计 | J4: 46082 | K4: 46083 | L4: 46084 | M4: 46085 | N4: 46086 | O4: 46087 | P4: 46088 | Q4: 46089 | R4: 46090 | S4: 46091 | T4: 46092 | U4: 46093 | V4: 46094 | W4: 46095 | X4: 46096 | Y4: 46097 | Z4: 46098 | AA4: 46099 | AB4: 46100 | AC4: 46101 | AD4: 46102 | AE4: 46103 | AF4: 46104 | AG4: 46105 | AH4: 46106 | AI4: 46107 | AJ4: 46108 | AK4: 46109 | AL4: 46110 | AM4: 46111 | AN4: 46112 | AO4: 出库合计 | AP4: 46082 | AQ4: 46113 | AR4: 46114 | AS4: 46115 | AT4: 46116 | AU4: 46117 | AV4: 46118 | AW4: 46119 | AX4: 46120 | AY4: 46121 | AZ4: 46122 | BA4: 46123 | BB4: 46124 | BC4: 46125 | BD4: 46126 | BE4: 46127 | BF4: 46128 | BG4: 46129 | BH4: 46130 | BI4: 46131 | BJ4: 46132 | BK4: 46133 | BL4: 46134 | BM4: 46135 | BN4: 46136 | BO4: 46137 | BP4: 46138 | BQ4: 46139 | BR4: 46140 | BS4: 46141 | BT4: 46142
B5: =VLOOKUP(D5,正方形!D:D,1,FALSE) -> #N/A | C5: =ROW()-4 -> 1 | D5: 10.5×7.5×4.5 | G5: 50 | H5: =G5+I5-AO5 -> 50 | I5: =SUM(J5:AN5) -> 0 | AO5: =SUM(AP5:BT5) -> 0
B6: =VLOOKUP(D6,正方形!D:D,1,FALSE) -> #N/A | C6: =ROW()-4 -> 2 | D6: 10.5×8.5×5.5(白) | F6: 23列-5-2 | G6: 20 | H6: =G6+I6-AO6 -> 20 | I6: =SUM(J6:AN6) -> 0 | AO6: =SUM(AP6:BT6) -> 0
B7: =VLOOKUP(D7,正方形!D:D,1,FALSE) -> #N/A | C7: =ROW()-4 -> 3 | D7: 10.8×9×3.3 | F7: 17列-1上 | G7: 500 | H7: =G7+I7-AO7 -> 500 | I7: =SUM(J7:AN7) -> 0 | AO7: =SUM(AP7:BT7) -> 0
C8: =ROW()-4 -> 4 | D8: 10×10×2(黑) | G8: 0 | H8: =G8+I8-AO8 -> -30 | I8: =SUM(J8:AN8) -> 0 | AO8: =SUM(AP8:BT8) -> 30 | AR8: 30
C9: =ROW()-4 -> 5 | D9: 10×10×3(黑) | G9: 0 | H9: =G9+I9-AO9 -> -30 | I9: =SUM(J9:AN9) -> 0 | AO9: =SUM(AP9:BT9) -> 30 | AR9: 30
B10: =VLOOKUP(D10,正方形!D:D,1,FALSE) -> #N/A | C10: =ROW()-4 -> 6 | D10: 10×10×3.5 | F10: 15列-1下 | G10: 700 | H10: =G10+I10-AO10 -> 700 | I10: =SUM(J10:AN10) -> 0 | AO10: =SUM(AP10:BT10) -> 0
C11: =ROW()-4 -> 7 | D11: 10×10×4(差) | G11: 0 | H11: =G11+I11-AO11 -> 0 | I11: =SUM(J11:AN11) -> 0 | AO11: =SUM(AP11:BT11) -> 0
C12: =ROW()-4 -> 8 | D12: 10×10×4(黑) | G12: 0 | H12: =G12+I12-AO12 -> -30 | I12: =SUM(J12:AN12) -> 200 | J12: 200 | AO12: =SUM(AP12:BT12) -> 230 | AP12: 200 | AR12: 30
B13: =VLOOKUP(D13,正方形!D:D,1,FALSE) -> #N/A | C13: =ROW()-4 -> 9 | D13: 10×10×5(差材料) | F13: 10列-9上 | G13: 150 | H13: =G13+I13-AO13 -> 150 | I13: =SUM(J13:AN13) -> 0 | AO13: =SUM(AP13:BT13) -> 0
B14: =VLOOKUP(D14,正方形!D:D,1,FALSE) -> #N/A | C14: =ROW()-4 -> 10 | D14: 10×10×5(黑) | F14: 18列-4中 | G14: 30 | H14: =G14+I14-AO14 -> 0 | I14: =SUM(J14:AN14) -> 0 | AO14: =SUM(AP14:BT14) -> 30 | AR14: 30
C15: =ROW()-4 -> 11 | D15: 10×10×6(黑) | G15: 0 | H15: =G15+I15-AO15 -> 0 | I15: =SUM(J15:AN15) -> 0 | AO15: =SUM(AP15:BT15) -> 0
B16: =VLOOKUP(D16,正方形!D:D,1,FALSE) -> #N/A | C16: =ROW()-4 -> 12 | D16: 10×10×7(黑) | G16: 0 | H16: =G16+I16-AO16 -> 0 | I16: =SUM(J16:AN16) -> 0 | AO16: =SUM(AP16:BT16) -> 0
B17: =VLOOKUP(D17,正方形!D:D,1,FALSE) -> #N/A | C17: =ROW()-4 -> 13 | D17: 10×5.5×4.5(白) | F17: 21列-5-3 | G17: 90 | H17: =G17+I17-AO17 -> 90 | I17: =SUM(J17:AN17) -> 0 | AO17: =SUM(AP17:BT17) -> 0
C18: =ROW()-4 -> 14 | D18: 10×6×2 | G18: 0 | H18: =G18+I18-AO18 -> 0 | I18: =SUM(J18:AN18) -> 0 | AO18: =SUM(AP18:BT18) -> 0
B19: =VLOOKUP(D19,正方形!D:D,1,FALSE) -> #N/A | C19: =ROW()-4 -> 15 | D19: 10×6×2(白) | F19: 25列-1-2 | G19: 0 | H19: =G19+I19-AO19 -> 0 | I19: =SUM(J19:AN19) -> 0 | AO19: =SUM(AP19:BT19) -> 0
B20: =VLOOKUP(D20,正方形!D:D,1,FALSE) -> #N/A | C20: =ROW()-4 -> 16 | D20: 10×6×3 | G20: 820 | H20: =G20+I20-AO20 -> 0 | I20: =SUM(J20:AN20) -> 0 | AO20: =SUM(AP20:BT20) -> 820 | AY20: 50 | BC20: 770
B21: =VLOOKUP(D21,正方形!D:D,1,FALSE) -> #N/A | C21: =ROW()-4 -> 17 | D21: 10×6×3(白) | F21: 25列-3-3/25列-4-下 | G21: 800 | H21: =G21+I21-AO21 -> 100 | I21: =SUM(J21:AN21) -> 0 | AO21: =SUM(AP21:BT21) -> 700 | AY21: 700
B22: =VLOOKUP(D22,正方形!D:D,1,FALSE) -> #N/A | C22: =ROW()-4 -> 18 | D22: 10×6×3(台) | F22: 19列-4中 | G22: 80 | H22: =G22+I22-AO22 -> 80 | I22: =SUM(J22:AN22) -> 0 | AO22: =SUM(AP22:BT22) -> 0
B23: =VLOOKUP(D23,正方形!D:D,1,FALSE) -> #N/A | C23: =ROW()-4 -> 19 | D23: 10×6×4 | F23: 4列-6上/10列-3上 | G23: 0 | H23: =G23+I23-AO23 -> 0 | I23: =SUM(J23:AN23) -> 0 | AO23: =SUM(AP23:BT23) -> 0
B24: =VLOOKUP(D24,正方形!D:D,1,FALSE) -> #N/A | C24: =ROW()-4 -> 20 | D24: 10×6×5 | G24: 0 | H24: =G24+I24-AO24 -> 0 | I24: =SUM(J24:AN24) -> 600 | J24: 600 | AO24: =SUM(AP24:BT24) -> 600 | AP24: =100+500 -> 600
B25: =VLOOKUP(D25,正方形!D:D,1,FALSE) -> #N/A | C25: =ROW()-4 -> 21 | D25: 10×6×5(白) | F25: 24列-1-2 | G25: 95 | H25: =G25+I25-AO25 -> 95 | I25: =SUM(J25:AN25) -> 0 | AO25: =SUM(AP25:BT25) -> 0
C26: =ROW()-4 -> 22 | D26: 10×6×6(白) | G26: 0 | H26: =G26+I26-AO26 -> 0 | I26: =SUM(J26:AN26) -> 0 | AO26: =SUM(AP26:BT26) -> 0
C27: =ROW()-4 -> 23 | D27: 10×7×1.7 | G27: 0 | H27: =G27+I27-AO27 -> 0 | I27: =SUM(J27:AN27) -> 0 | AO27: =SUM(AP27:BT27) -> 0
B28: =VLOOKUP(D28,正方形!D:D,1,FALSE) -> #N/A | C28: =ROW()-4 -> 24 | D28: 10×7×3 | G28: 0 | H28: =G28+I28-AO28 -> 0 | I28: =SUM(J28:AN28) -> 0 | AO28: =SUM(AP28:BT28) -> 0
B29: =VLOOKUP(D29,正方形!D:D,1,FALSE) -> #N/A | C29: =ROW()-4 -> 25 | D29: 10×7×3(黑) | F29: 18列-5中 | G29: 20 | H29: =G29+I29-AO29 -> 20 | I29: =SUM(J29:AN29) -> 0 | AO29: =SUM(AP29:BT29) -> 0
B30: =VLOOKUP(D30,正方形!D:D,1,FALSE) -> #N/A | C30: =ROW()-4 -> 26 | D30: 10×7×3(台) | F30: 19列-4中 | G30: 400 | H30: =G30+I30-AO30 -> 400 | I30: =SUM(J30:AN30) -> 0 | AO30: =SUM(AP30:BT30) -> 0
B31: =VLOOKUP(D31,正方形!D:D,1,FALSE) -> #N/A | C31: =ROW()-4 -> 27 | D31: 10×7×4白 | F31: 9列-3下 | G31: 460 | H31: =G31+I31-AO31 -> 460 | I31: =SUM(J31:AN31) -> 0 | AO31: =SUM(AP31:BT31) -> 0
B32: =VLOOKUP(D32,正方形!D:D,1,FALSE) -> #N/A | C32: =ROW()-4 -> 28 | D32: 10×7×4(白) | F32: 24列-4-下 | G32: 570 | H32: =G32+I32-AO32 -> 570 | I32: =SUM(J32:AN32) -> 0 | AO32: =SUM(AP32:BT32) -> 0
B33: =VLOOKUP(D33,正方形!D:D,1,FALSE) -> #N/A | C33: =ROW()-4 -> 29 | D33: 10×7×5 | G33: 0 | H33: =G33+I33-AO33 -> 0 | I33: =SUM(J33:AN33) -> 0 | AO33: =SUM(AP33:BT33) -> 0
B34: =VLOOKUP(D34,正方形!D:D,1,FALSE) -> #N/A | C34: =ROW()-4 -> 30 | D34: 10×7×5(台) | F34: 19列-2中 | G34: 290 | H34: =G34+I34-AO34 -> 290 | I34: =SUM(J34:AN34) -> 0 | AO34: =SUM(AP34:BT34) -> 0
B35: =VLOOKUP(D35,正方形!D:D,1,FALSE) -> #N/A | C35: =ROW()-4 -> 31 | D35: 10×7×6 | G35: 0 | H35: =G35+I35-AO35 -> 0 | I35: =SUM(J35:AN35) -> 0 | AO35: =SUM(AP35:BT35) -> 0
B36: =VLOOKUP(D36,正方形!D:D,1,FALSE) -> #N/A | C36: =ROW()-4 -> 32 | D36: 10×7×7 | F36: 216列-9上 | G36: 40 | H36: =G36+I36-AO36 -> 0 | I36: =SUM(J36:AN36) -> 0 | AO36: =SUM(AP36:BT36) -> 40 | BP36: 40
B37: =VLOOKUP(D37,正方形!D:D,1,FALSE) -> #N/A | C37: =ROW()-4 -> 33 | D37: 10×8×2 | F37: 12列-5上 | G37: =40-40 -> 0 | H37: =G37+I37-AO37 -> 0 | I37: =SUM(J37:AN37) -> 500 | J37: 500 | AO37: =SUM(AP37:BT37) -> 500 | AP37: 500
B38: =VLOOKUP(D38,正方形!D:D,1,FALSE) -> #N/A | C38: =ROW()-4 -> 34 | I38: =SUM(J38:AN38) -> 0 | AO38: =SUM(AP38:BT38) -> 0
B39: =VLOOKUP(D39,正方形!D:D,1,FALSE) -> #N/A | C39: =ROW()-4 -> 35 | D39: 10×8×3(白) | F39: 25列-4-下 | G39: 50 | H39: =G39+I39-AO39 -> 0 | I39: =SUM(J39:AN39) -> 0 | AO39: =SUM(AP39:BT39) -> 50 | BE39: 50
B40: =VLOOKUP(D40,正方形!D:D,1,FALSE) -> #N/A | C40: =ROW()-4 -> 36 | D40: 10×8×3(台) | F40: 19列-4中 | G40: 600 | H40: =G40+I40-AO40 -> 600 | I40: =SUM(J40:AN40) -> 0 | AO40: =SUM(AP40:BT40) -> 0
C41: =ROW()-4 -> 37 | D41: 10×8×4 | G41: 0 | H41: =G41+I41-AO41 -> -500 | I41: =SUM(J41:AN41) -> 0 | AO41: =SUM(AP41:BT41) -> 500 | AR41: 500
...

Sheet 正方形
D1: 26年3月仓库正方形飞机盒台帐(普通、台湾、白)
C3: 序号 | D3: 外尺寸规格 | E3: 内尺寸规格 | F3: 货位 | G3: 上月在库 | H3: 库存 | I3: 入库记录 | AO3: 出库记录
I4: 入库合计 | J4: 46082 | K4: 46083 | L4: 46084 | M4: 46085 | N4: 46086 | O4: 46087 | P4: 46088 | Q4: 46089 | R4: 46090 | S4: 46091 | T4: 46092 | U4: 46093 | V4: 46094 | W4: 46095 | X4: 46096 | Y4: 46097 | Z4: 46098 | AA4: 46099 | AB4: 46100 | AC4: 46101 | AD4: 46102 | AE4: 46103 | AF4: 46104 | AG4: 46105 | AH4: 46106 | AI4: 46107 | AJ4: 46108 | AK4: 46109 | AL4: 46110 | AM4: 46111 | AN4: 46112 | AO4: 出库合计 | AP4: 46082 | AQ4: 46083 | AR4: 46084 | AS4: 46085 | AT4: 46086 | AU4: 46087 | AV4: 46088 | AW4: 46089 | AX4: 46090 | AY4: 46091 | AZ4: 46092 | BA4: 46093 | BB4: 46094 | BC4: 46095 | BD4: 46096 | BE4: 46097 | BF4: 46098 | BG4: 46099 | BH4: 46100 | BI4: 46101 | BJ4: 46102 | BK4: 46103 | BL4: 46104 | BM4: 46105 | BN4: 46106 | BO4: 46107 | BP4: 46108 | BQ4: 46109 | BR4: 46110 | BS4: 46111 | BT4: 46112
C5: =ROW()-4 -> 1 | D5: 6×6×2 | H5: =G5+I5-AO5 -> 0 | I5: =SUM(J5:AN5) -> 0 | AO5: =SUM(AP5:BT5) -> 0
C6: =ROW()-4 -> 2 | D6: 6×6×2(白) | G6: 0 | H6: =G6+I6-AO6 -> 0 | I6: =SUM(J6:AN6) -> 0 | AO6: =SUM(AP6:BT6) -> 0
C7: =ROW()-4 -> 3 | D7: 7×7×2 | H7: =G7+I7-AO7 -> 0 | I7: =SUM(J7:AN7) -> 0 | AO7: =SUM(AP7:BT7) -> 0
C8: =ROW()-4 -> 4 | D8: 7×7×2(白) | G8: 0 | H8: =G8+I8-AO8 -> 0 | I8: =SUM(J8:AN8) -> 0 | AO8: =SUM(AP8:BT8) -> 0
C9: =ROW()-4 -> 5 | D9: 8×8×2 | H9: =G9+I9-AO9 -> -300 | I9: =SUM(J9:AN9) -> 0 | AO9: =SUM(AP9:BT9) -> 300 | AP9: 300
C10: =ROW()-4 -> 6 | D10: 8×8×2(白) | G10: 0 | H10: =G10+I10-AO10 -> 0 | I10: =SUM(J10:AN10) -> 0 | AO10: =SUM(AP10:BT10) -> 0
C11: =ROW()-4 -> 7 | D11: 9×9×2 | H11: =G11+I11-AO11 -> 0 | I11: =SUM(J11:AN11) -> 0 | AO11: =SUM(AP11:BT11) -> 0
C12: =ROW()-4 -> 8 | D12: 9×9×2(白) | G12: 0 | H12: =G12+I12-AO12 -> 0 | I12: =SUM(J12:AN12) -> 0 | AO12: =SUM(AP12:BT12) -> 0
C13: =ROW()-4 -> 9 | D13: 10×10×2 | H13: =G13+I13-AO13 -> 160 | I13: =SUM(J13:AN13) -> 160 | J13: =100+60 -> 160 | AO13: =SUM(AP13:BT13) -> 0
C14: =ROW()-4 -> 10 | D14: 10×10×2(白) | H14: =G14+I14-AO14 -> 0 | I14: =SUM(J14:AN14) -> 0 | AO14: =SUM(AP14:BT14) -> 0
C15: =ROW()-4 -> 11 | D15: 10×10×2(台) | H15: =G15+I15-AO15 -> 0 | I15: =SUM(J15:AN15) -> 0 | AO15: =SUM(AP15:BT15) -> 0
C16: =ROW()-4 -> 12 | D16: 11×11×2 | H16: =G16+I16-AO16 -> 50 | I16: =SUM(J16:AN16) -> 50 | J16: 50 | AO16: =SUM(AP16:BT16) -> 0
C17: =ROW()-4 -> 13 | D17: 11×11×2(白) | G17: 0 | H17: =G17+I17-AO17 -> 0 | I17: =SUM(J17:AN17) -> 0 | AO17: =SUM(AP17:BT17) -> 0
C18: =ROW()-4 -> 14 | D18: 12×12×2 | H18: =G18+I18-AO18 -> -2000 | I18: =SUM(J18:AN18) -> 100 | J18: 100 | AO18: =SUM(AP18:BT18) -> 2100 | AQ18: =600+1500 -> 2100
C19: =ROW()-4 -> 15 | D19: 12×12×2(台) | H19: =G19+I19-AO19 -> 0 | I19: =SUM(J19:AN19) -> 0 | AO19: =SUM(AP19:BT19) -> 0
C20: =ROW()-4 -> 16 | D20: 13×13×2 | H20: =G20+I20-AO20 -> -600 | I20: =SUM(J20:AN20) -> 0 | AO20: =SUM(AP20:BT20) -> 600 | AP20: =500+30 -> 530 | AQ20: 70
C21: =ROW()-4 -> 17 | D21: 13×13×2(台) | H21: =G21+I21-AO21 -> 0 | I21: =SUM(J21:AN21) -> 0 | AO21: =SUM(AP21:BT21) -> 0
C22: =ROW()-4 -> 18 | D22: 13×13×2(白) | H22: =G22+I22-AO22 -> 0 | I22: =SUM(J22:AN22) -> 0 | AO22: =SUM(AP22:BT22) -> 0
C23: =ROW()-4 -> 19 | D23: 14×14×2 | H23: =G23+I23-AO23 -> 0 | I23: =SUM(J23:AN23) -> 0 | AO23: =SUM(AP23:BT23) -> 0
C24: =ROW()-4 -> 20 | D24: 14×14×2(台) | H24: =G24+I24-AO24 -> 0 | I24: =SUM(J24:AN24) -> 0 | AO24: =SUM(AP24:BT24) -> 0
C25: =ROW()-4 -> 21 | D25: 14×14×2(白) | H25: =G25+I25-AO25 -> 0 | I25: =SUM(J25:AN25) -> 0 | AO25: =SUM(AP25:BT25) -> 0
C26: =ROW()-4 -> 22 | D26: 15×15×2 | H26: =G26+I26-AO26 -> -100 | I26: =SUM(J26:AN26) -> 0 | AO26: =SUM(AP26:BT26) -> 100 | AQ26: 100
C27: =ROW()-4 -> 23 | D27: 15×15×2(白) | G27: 0 | H27: =G27+I27-AO27 -> 0 | I27: =SUM(J27:AN27) -> 0 | AO27: =SUM(AP27:BT27) -> 0
C28: =ROW()-4 -> 24 | D28: 16×16×2 | H28: =G28+I28-AO28 -> -801 | I28: =SUM(J28:AN28) -> 70 | J28: 70 | AO28: =SUM(AP28:BT28) -> 871 | AP28: =1+70 -> 71 | AQ28: 800
C29: =ROW()-4 -> 25 | D29: 16×16×2(台) | H29: =G29+I29-AO29 -> 0 | I29: =SUM(J29:AN29) -> 0 | AO29: =SUM(AP29:BT29) -> 0
C30: =ROW()-4 -> 26 | D30: 17×17×2 | H30: =G30+I30-AO30 -> 50 | I30: =SUM(J30:AN30) -> 50 | K30: 50 | AO30: =SUM(AP30:BT30) -> 0
C31: =ROW()-4 -> 27 | D31: 17×17×2(白) | G31: 0 | H31: =G31+I31-AO31 -> 0 | I31: =SUM(J31:AN31) -> 0 | AO31: =SUM(AP31:BT31) -> 0
C32: =ROW()-4 -> 28 | D32: 18×18×2(卡) | H32: =G32+I32-AO32 -> 0 | I32: =SUM(J32:AN32) -> 0 | AO32: =SUM(AP32:BT32) -> 0
C33: =ROW()-4 -> 29 | D33: 18×18×2 | H33: =G33+I33-AO33 -> 0 | I33: =SUM(J33:AN33) -> 0 | AO33: =SUM(AP33:BT33) -> 0
C34: =ROW()-4 -> 30 | D34: 18×18×2(台） | H34: =G34+I34-AO34 -> 0 | I34: =SUM(J34:AN34) -> 0 | AO34: =SUM(AP34:BT34) -> 0
C35: =ROW()-4 -> 31 | D35: 19×19×2 | H35: =G35+I35-AO35 -> 350 | I35: =SUM(J35:AN35) -> 350 | J35: 350 | AO35: =SUM(AP35:BT35) -> 0
C36: =ROW()-4 -> 32 | D36: 19×19×2(白) | G36: 0 | H36: =G36+I36-AO36 -> 0 | I36: =SUM(J36:AN36) -> 0 | AO36: =SUM(AP36:BT36) -> 0
C37: =ROW()-4 -> 33 | D37: 20×20×2 | H37: =G37+I37-AO37 -> 0 | I37: =SUM(J37:AN37) -> 200 | J37: 200 | AO37: =SUM(AP37:BT37) -> 200 | AP37: 200
C38: =ROW()-4 -> 34 | D38: 20×20×2(白) | G38: 0 | H38: =G38+I38-AO38 -> -100 | I38: =SUM(J38:AN38) -> 0 | AO38: =SUM(AP38:BT38) -> 100 | AQ38: 100
C39: =ROW()-4 -> 35 | D39: 20×20×2(卡) | H39: =G39+I39-AO39 -> 0 | I39: =SUM(J39:AN39) -> 0 | AO39: =SUM(AP39:BT39) -> 0
C40: =ROW()-4 -> 36 | D40: 20×20×2(台) | H40: =G40+I40-AO40 -> 0 | I40: =SUM(J40:AN40) -> 0 | AO40: =SUM(AP40:BT40) -> 0
C41: =ROW()-4 -> 37 | D41: 21×21×2 | H41: =G41+I41-AO41 -> 59 | I41: =SUM(J41:AN41) -> 60 | J41: 60 | AO41: =SUM(AP41:BT41) -> 1 | AP41: 1
...

Sheet 转换
E1: ×
E2: 18.5 | F2: 8.5 | G2: 2.5 | H2: =E2&$E$1&F2&$E$1&G2 -> 18.5×8.5×2.5
E3: 9 | F3: 7 | G3: 2 | H3: =E3&$E$1&F3&$E$1&G3 -> 9×7×2
E4: 21 | F4: 14 | G4: 11.5 | H4: =E4&$E$1&F4&$E$1&G4 -> 21×14×11.5
E5: 40.5 | F5: 14.5 | G5: 3.5 | H5: =E5&$E$1&F5&$E$1&G5 -> 40.5×14.5×3.5
E6: 28 | F6: 18 | G6: 4 | H6: =E6&$E$1&F6&$E$1&G6 -> 28×18×4
E7: 21 | F7: 16 | G7: 10 | H7: =E7&$E$1&F7&$E$1&G7 -> 21×16×10
E8: 19 | F8: 8 | G8: 5 | H8: =E8&$E$1&F8&$E$1&G8 -> 19×8×5
E9: 25.5 | F9: 13.5 | G9: 9.5 | H9: =E9&$E$1&F9&$E$1&G9 -> 25.5×13.5×9.5
E10: 15 | F10: 11 | G10: 6 | H10: =E10&$E$1&F10&$E$1&G10 -> 15×11×6
E11: 17 | F11: 11 | G11: 6 | H11: =E11&$E$1&F11&$E$1&G11 -> 17×11×6
E12: 14.5 | F12: 10.5 | G12: 5.5 | H12: =E12&$E$1&F12&$E$1&G12 -> 14.5×10.5×5.5
E13: 29 | F13: 16 | G13: 5 | H13: =E13&$E$1&F13&$E$1&G13 -> 29×16×5
... E15: 26.5 | F15: 15.5 | G15: 10.5 | H15: =E15&$E$1&F15&$E$1&G15 -> 26.5×15.5×10.5
E16: 19×13.5×12.5 | H16: =E16&$E$1&F16&$E$1&G16 -> 19×13.5×12.5××
E17: 43×35×10 | H17: =E17&$E$1&F17&$E$1&G17 -> 43×35×10××
E18: 24×18×2 | H18: =E18&$E$1&F18&$E$1&G18 -> 24×18×2××
E19: 39.5×33.5×3.5 | H19: =E19&$E$1&F19&$E$1&G19 -> 39.5×33.5×3.5××
E20: 38 | F20: 17 | G20: 2 | H20: =E20&$E$1&F20&$E$1&G20 -> 38×17×2
E21: 30.5 | F21: 11.5 | G21: 8.5 | H21: =E21&$E$1&F21&$E$1&G21 -> 30.5×11.5×8.5
E22: 19 | F22: 12 | G22: 7 | H22: =E22&$E$1&F22&$E$1&G22 -> 19×12×7
E23: 32 | F23: 11 | G23: 7 | H23: =E23&$E$1&F23&$E$1&G23 -> 32×11×7
E24: 23 | F24: 6 | G24: 6 | H24: =E24&$E$1&F24&$E$1&G24 -> 23×6×6
E25: 17 | F25: 16 | G25: 5（黑） | H25: =E25&$E$1&F25&$E$1&G25 -> 17×16×5（黑）
E26: 10.5 | F26: 7.5 | G26: 2.5 | H26: =E26&$E$1&F26&$E$1&G26 -> 10.5×7.5×2.5
E27: 43 | F27: 9 | G27: 9 | H27: =E27&$E$1&F27&$E$1&G27 -> 43×9×9
E28: 22 | F28: 6 | G28: 6 | H28: =E28&$E$1&F28&$E$1&G28 -> 22×6×6
E29: 25 | F29: 17 | G29: 9 | H29: =E29&$E$1&F29&$E$1&G29 -> 25×17×9
E30: 10.5 | F30: 7.5 | G30: 6.5 | H30: =E30&$E$1&F30&$E$1&G30 -> 10.5×7.5×6.5
E31: 34.5 | F31: 8.5 | G31: 4.5 | H31: =E31&$E$1&F31&$E$1&G31 -> 34.5×8.5×4.5
E32: 45 | F32: 35 | G32: 5 | H32: =E32&$E$1&F32&$E$1&G32 -> 45×35×5
E33: 45 | F33: 35 | G33: 8 | H33: =E33&$E$1&F33&$E$1&G33 -> 45×35×8
E34: 45 | F34: 35 | G34: 12 | H34: =E34&$E$1&F34&$E$1&G34 -> 45×35×12
E35: 27 | F35: 8 | G35: 7 | H35: =E35&$E$1&F35&$E$1&G35 -> 27×8×7
E36: 20 | F36: 18 | G36: 3（白） | H36: =E36&$E$1&F36&$E$1&G36 -> 20×18×3（白）
E37: 35 | F37: 25 | G37: 3（白） | H37: =E37&$E$1&F37&$E$1&G37 -> 35×25×3（白）
E38: 35 | F38: 13 | G38: 3 | H38: =E38&$E$1&F38&$E$1&G38 -> 35×13×3
E39: 19 | F39: 12 | G39: 12 | H39: =E39&$E$1&F39&$E$1&G39 -> 19×12×12
E40: 22 | F40: 14 | G40: 12 | H40: =E40&$E$1&F40&$E$1&G40 -> 22×14×12
E41: 24 | F41: 15 | G41: 7 | H41: =E41&$E$1&F41&$E$1&G41 -> 24×15×7
...

Sheet 出入库记录
B2: 产品数量
B3: 项目 | C3: 类别 | D3: 46082 | E3: 46083 | F3: 46084 | G3: 46085 | H3: 46086 | I3: 46087 | J3: 46088 | K3: 46089 | L3: 46090 | M3: 46091 | N3: 46092 | O3: 46093 | P3: 46094 | Q3: 46095 | R3: 46096 | S3: 46097 | T3: 46098 | U3: 46099 | V3: 46100 | W3: 46101 | X3: 46102 | Y3: 46103 | Z3: 46104 | AA3: 46105 | AB3: 46106 | AC3: 46107 | AD3: 46108 | AE3: 46109 | AF3: 46110 | AG3: 46111 | AH3: 46112
B4: 入 | C4: 正方形 | D4: =正方形!J1636 -> 19361 | E4: =正方形!K1636 -> 5226 | F4: =正方形!L1636 -> 0 | G4: =正方形!M1636 -> 0 | H4: =正方形!N1636 -> 0 | I4: =正方形!O1636 -> 0 | J4: =正方形!P1636 -> 0 | K4: =正方形!Q1636 -> 0 | ... AH4: =正方形!AN1636 -> 0
C5: 长方形 | D5: =长方形!J4507 -> 31333 | E5: =长方形!K4507 -> 300 | F5: =长方形!L4507 -> 0 | G5: =长方形!M4507 -> 0 | H5: =长方形!N4507 -> 0 | I5: =长方形!O4507 -> 0 | J5: =长方形!P4507 -> 0 | K5: =长方形!Q4507 -> 0 | ... AH5: =长方形!AN4507 -> 0
C6: 合计 | D6: =D5+D4 -> 50694 | E6: =E5+E4 -> 5526 | F6: =F5+F4 -> 0 | G6: =G5+G4 -> 0 | H6: =H5+H4 -> 0 | I6: =I5+I4 -> 0 | J6: =J5+J4 -> 0 | K6: =K5+K4 -> 0 | ... AH6: =AH5+AH4 -> 0
B7: 出 | C7: 正方形 | D7: =正方形!AQ1636 -> 16159 | E7: =正方形!AR1636 -> 0 | F7: =正方形!AS1636 -> 0 | G7: =正方形!AT1636 -> 0 | H7: =正方形!AU1636 -> 0 | I7: =正方形!AV1636 -> 0 | J7: =正方形!AW1636 -> 0 | K7: =正方形!AX1636 -> 0 | ... AH7: =正方形!BU1636 -> 0
C8: 长方形 | D8: =长方形!AR4507 -> 40554 | E8: =长方形!AS4507 -> 1686 | F8: =长方形!AT4507 -> 800 | G8: =长方形!AU4507 -> 1490 | H8: =长方形!AV4507 -> 1252 | I8: =长方形!AW4507 -> 2100 | J8: =长方形!AX4507 -> 2068 | K8: =长方形!AY4507 -> 3424 | ... AF8: =长方形!BT4507 -> 718 | AG8: =长方形!#REF! -> #REF! | AH8: =长方形!BU4507 -> 0
C9: 合计 | D9: =D7+D8 -> 56713 | E9: =E7+E8 -> 1686 | F9: =F7+F8 -> 800 | G9: =G7+G8 -> 1490 | H9: =H7+H8 -> 1252 | I9: =I7+I8 -> 2100 | J9: =J7+J8 -> 2068 | K9: =K7+K8 -> 3424 | ... AH9: =AH7+AH8 -> 0
B10: 入-出 | D10: =D6-D9 -> -6019 | E10: =E6-E9 -> 3840 | F10: =F6-F9 -> -800 | G10: =G6-G9 -> -1490 | H10: =H6-H9 -> -1252 | I10: =I6-I9 -> -2100 | J10: =J6-J9 -> -2068 | K10: =K6-K9 -> -3424 | ... AH10: =AH6-AH9 -> 0
B14: 产品种类数
B15: 项目 | C15: 类别 | D15: 46082 | E15: 46083 | F15: 46084 | G15: 46085 | H15: 46086 | I15: 46087 | J15: 46088 | K15: 46089 | L15: 46090 | M15: 46091 | N15: 46092 | O15: 46093 | P15: 46094 | Q15: 46095 | R15: 46096 | S15: 46097 | T15: 46098 | U15: 46099 | V15: 46100 | W15: 46101 | X15: 46102 | Y15: 46103 | Z15: 46104 | AA15: 46105 | AB15: 46106 | AC15: 46107 | AD15: 46108 | AE15: 46109 | AF15: 46110 | AG15: 46111 | AH15: 46112
B16: 入 | C16: 正方形 | D16: =COUNT(正方形!J$5:J$1632)*1.1 -> 62.7 | E16: =COUNT(正方形!K$5:K$1632)*1.1 -> 14.3 | F16: =COUNT(正方形!L$5:L$1632)*1.1 -> 0 | G16: =COUNT(正方形!M$5:M$1632)*1.1 -> 0 | H16: =COUNT(正方形!N$5:N$1632)*1.1 -> 0 | I16: =COUNT(正方形!O$5:O$1632)*1.1 -> 0 | J16: =COUNT(正方形!P$5:P$1632)*1.1 -> 0 | K16: =COUNT(正方形!Q$5:Q$1632)*1.1 -> 0 | ... AH16: =COUNT(正方形!AN$5:AN$1632)*1.1 -> 0
C17: 长方形 | D17: =COUNT(长方形!J$5:J$3614) -> 201 | E17: =COUNT(长方形!K$5:K$3614) -> 2 | F17: =COUNT(长方形!L$5:L$3614) -> 0 | G17: =COUNT(长方形!M$5:M$3614) -> 0 | H17: =COUNT(长方形!N$5:N$3614) -> 0 | I17: =COUNT(长方形!O$5:O$3614) -> 0 | J17: =COUNT(长方形!P$5:P$3614) -> 0 | K17: =COUNT(长方形!Q$5:Q$3614) -> 0 | ... AH17: =COUNT(长方形!AN$5:AN$3614) -> 0
C18: 合计 | D18: =D17+D16 -> 263.7 | E18: =E17+E16 -> 16.3 | F18: =F17+F16 -> 0 | G18: =G17+G16 -> 0 | H18: =H17+H16 -> 0 | I18: =I17+I16 -> 0 | J18: =J17+J16 -> 0 | K18: =K17+K16 -> 0 | ... AH18: =AH17+AH16 -> 0
B19: 出 | C19: 正方形 | D19: =COUNT(正方形!AQ$5:AQ1632)*1.1 -> 85.8 | E19: =COUNT(正方形!AR$5:AR1632)*1.1 -> 0 | F19: =COUNT(正方形!AS$5:AS1632)*1.1 -> 0 | G19: =COUNT(正方形!AT$5:AT1632)*1.1 -> 0 | H19: =COUNT(正方形!AU$5:AU1632)*1.1 -> 0 | I19: =COUNT(正方形!AV$5:AV1632)*1.1 -> 0 | J19: =COUNT(正方形!AW$5:AW1632)*1.7 -> 0 | K19: =COUNT(正方形!AX$5:AX1632)*1.1 -> 0 | L19: =COUNT(正方形!AY$5:AY1632)*1.1 -> 0 | M19: =COUNT(正方形!AZ$5:AZ1632)*1.2 -> 0 | N19: =COUNT(正方形!BA$5:BA1632)*1.1 -> 0 | O19: =COUNT(正方形!BB$5:BB1632)*1.1 -> 0 | P19: =COUNT(正方形!BC$5:BC1632)*1.1 -> 0 | Q19: =COUNT(正方形!BD$5:BD1632)*1.1 -> 0 | R19: =COUNT(正方形!BE$5:BE1632)*1.1 -> 0 | S19: =COUNT(正方形!BF$5:BF1632)*1.1 -> 0 | T19: =COUNT(正方形!BG$5:BG1632)*1.1 -> 0 | U19: =COUNT(正方形!BH$5:BH1632)*1.1 -> 0 | ... AH19: =COUNT(正方形!BU$5:BU1632)*1.1 -> 0
C20: 长方形 | D20: =COUNT(长方形!AR$5:AR$3614)*1.1 -> 236.5 | E20: =COUNT(长方形!AS$5:AS$3614)*1.1 -> 22 | F20: =COUNT(长方形!AT$5:AT$3614)*1.1 -> 3.3 | G20: =COUNT(长方形!AU$5:AU$3614)*1.1 -> 24.2 | H20: =COUNT(长方形!AV$5:AV$3614)*1.1 -> 15.4 | I20: =COUNT(长方形!AW$5:AW$3614)*1.1 -> 23.1 | J20: =COUNT(长方形!AX$5:AX$3614)*1.1 -> 17.6 | K20: =COUNT(长方形!AY$5:AY$3614)*1.1 -> 35.2 | ... AF20: =COUNT(长方形!BT$5:BT$3614)*1.1 -> 20.9 | AG20: =COUNT(长方形!#REF!)*1.1 -> 0 | AH20: =COUNT(长方形!BU$5:BU$3614)*1.1 -> 0
C21: 合计 | D21: =D19+D20 -> 322.3 | E21: =E19+E20 -> 22 | F21: =F19+F20 -> 3.3 | G21: =G19+G20 -> 24.2 | H21: =H19+H20 -> 15.4 | I21: =I19+I20 -> 23.1 | J21: =J19+J20 -> 17.6 | K21: =K19+K20 -> 35.2 | ... AH21: =AH19+AH20 -> 0

Sheet Sheet2

Sheet 台帐记录方法
C3: 入库 | D3: 根据登记表，把入库数量输入对应的规格当日入库记录里，表内没有规格的，新增一行
D4: 每天把出库数据做完后，对于长方形的，筛选在库小于0的，把欠料数量输入当天的入库记录里。
D5: 在库20个以下，发货超过20，不取出来，直接欠多少生产多少
C7: 出库 | D7: 根据发货单，把发货数据填入对应规格的当日出库记录，同一规格有多条记录的，按*+*+*+依次记入
C11: 月底更新台帐 | D11: 保存当月的台帐后，另存一份次月的
D12: 把库存数据全部粘贴在上月在库（只粘贴数值）
D13: 清除所有的出入库记录
D14: 更改文件名的月份

Sheet Sheet1
E3: 6×6×2 | F3: =VLOOKUP(E3,Sheet3!F:G,2,FALSE) -> #N/A | H3: 10×10×2 | I3: 白) | J3: 白) | K3: =E3&"(台)" -> 6×6×2(台)
E4: 7×7×2 | F4: =VLOOKUP(E4,Sheet3!F:G,2,FALSE) -> #N/A | H4: 10×10×2 | I4: 台) | J4: 台) | K4: =E4&"(台)" -> 7×7×2(台)
E5: 8×8×2 | F5: =VLOOKUP(E5,Sheet3!F:G,2,FALSE) -> #N/A | H5: 12×12×2 | I5: 台) | J5: 台) | K5: =E5&"(台)" -> 8×8×2(台)
E6: 9×9×2 | F6: =VLOOKUP(E6,Sheet3!F:G,2,FALSE) -> #N/A | H6: 13×13×2 | I6: 台) | J6: 台) | K6: =E6&"(台)" -> 9×9×2(台)
E7: 10×10×2 | F7: =VLOOKUP(E7,Sheet3!F:G,2,FALSE) -> 台) | H7: 13×13×2 | J7: 白)
E8: 11×11×2 | F8: =VLOOKUP(E8,Sheet3!F:G,2,FALSE) -> #N/A | H8: 13×13×2 | I8: 白) | J8: 台) | K8: =E8&"(台)" -> 11×11×2(台)
E9: 12×12×2 | F9: =VLOOKUP(E9,Sheet3!F:G,2,FALSE) -> 台) | H9: 14×14×2 | J9: 白)
E10: 13×13×2 | F10: =VLOOKUP(E10,Sheet3!F:G,2,FALSE) -> 台) | H10: 16×16×2 | J10: 台)
E11: 14×14×2 | F11: =VLOOKUP(E11,Sheet3!F:G,2,FALSE) -> 0 | H11: 18×18×2 | J11: 卡)
E12: 15×15×2 | F12: =VLOOKUP(E12,Sheet3!F:G,2,FALSE) -> #N/A | H12: 14×14×2 | I12: 台) | J12: 卡) | K12: =E12&"(台)" -> 15×15×2(台)
E13: 16×16×2 | F13: =VLOOKUP(E13,Sheet3!F:G,2,FALSE) -> 0 | H13: 20×20×2 | J13: 台)
E14: 17×17×2 | F14: =VLOOKUP(E14,Sheet3!F:G,2,FALSE) -> #N/A | H14: 14×14×2 | I14: 白) | J14: 台) | K14: =E14&"(台)" -> 17×17×2(台)
E15: 18×18×2 | F15: =VLOOKUP(E15,Sheet3!F:G,2,FALSE) -> 0 | H15: 31×31×2 | J15: 白)
E16: 19×19×2 | F16: =VLOOKUP(E16,Sheet3!F:G,2,FALSE) -> #N/A | H16: 16×16×2 | I16: 台) | J16: 白) | K16: =E16&"(台)" -> 19×19×2(台)
E17: 20×20×2 | F17: =VLOOKUP(E17,Sheet3!F:G,2,FALSE) -> 0 | H17: 9×9×3 | J17: 白)
E18: 21×21×2 | F18: =VLOOKUP(E18,Sheet3!F:G,2,FALSE) -> 台) | H18: 9×9×3 | J18: 台)
E19: 22×22×2 | F19: =VLOOKUP(E19,Sheet3!F:G,2,FALSE) -> #N/A | H19: 18×18×2 | I19: 卡) | J19: 白) | K19: =E19&"(台)" -> 22×22×2(台)
E20: 23×23×2 | F20: =VLOOKUP(E20,Sheet3!F:G,2,FALSE) -> #N/A | H20: 20×20×2 | I20: 卡) | J20: 白) | K20: =E20&"(台)" -> 23×23×2(台)
E21: 24×24×2 | F21: =VLOOKUP(E21,Sheet3!F:G,2,FALSE) -> #N/A | H21: 20×20×2 | I21: 台) | J21: 白) | K21: =E21&"(台)" -> 24×24×2(台)
E22: 25×25×2 | F22: =VLOOKUP(E22,Sheet3!F:G,2,FALSE) -> #N/A | H22: 21×21×2 | I22: 台) | J22: 台) | K22: =E22&"(台)" -> 25×25×2(台)
E23: 26×26×2 | F23: =VLOOKUP(E23,Sheet3!F:G,2,FALSE) -> #N/A | H23: 30×30×2 | I23: 台) | J23: 白) | K23: =E23&"(台)" -> 26×26×2(台)
E24: 27×27×2 | F24: =VLOOKUP(E24,Sheet3!F:G,2,FALSE) -> #N/A | H24: 31×31×2 | I24: 白) | J24: 台) | K24: =E24&"(台)" -> 27×27×2(台)
E25: 28×28×2 | F25: =VLOOKUP(E25,Sheet3!F:G,2,FALSE) -> #N/A | H25: 7×7×3 | I25: 白) | J25: 台) | K25: =E25&"(台)" -> 28×28×2(台)
E26: 29×29×2 | F26: =VLOOKUP(E26,Sheet3!F:G,2,FALSE) -> #N/A | H26: 9×9×3 | I26: 白) | J26: 白) | K26: =E26&"(台)" -> 29×29×2(台)
E27: 30×30×2 | F27: =VLOOKUP(E27,Sheet3!F:G,2,FALSE) -> 台) | H27: 9×9×3 | I27: 台) | J27: 台) | K27: =E27&"(白)" -> 30×30×2(白)
E28: 31×31×2 | F28: =VLOOKUP(E28,Sheet3!F:G,2,FALSE) -> 0 | H28: 16×16×3 | J28: 白)
E29: 32×32×2 | F29: =VLOOKUP(E29,Sheet3!F:G,2,FALSE) -> #N/A | H29: 10×10×3 | I29: 白) | J29: 台) | K29: =E29&"(台)" -> 32×32×2(台)
E30: 33×33×2 | F30: =VLOOKUP(E30,Sheet3!F:G,2,FALSE) -> #N/A | H30: 11×11×3 | I30: 白) | J30: 白) | K30: =E30&"(台)" -> 33×33×2(台)
E31: 34×34×2 | F31: =VLOOKUP(E31,Sheet3!F:G,2,FALSE) -> #N/A | H31: 12×12×3 | I31: 白) | J31: 台) | K31: =E31&"(台)" -> 34×34×2(台)
E32: 35×35×2 | F32: =VLOOKUP(E32,Sheet3!F:G,2,FALSE) -> #N/A | H32: 12×12×3 | I32: 台) | J32: 台) | K32: =E32&"(台)" -> 35×35×2(台)
E33: 36×36×2 | F33: =VLOOKUP(E33,Sheet3!F:G,2,FALSE) -> #N/A | H33: 13×13×3 | I33: 白) | J33: 白) | K33: =E33&"(台)" -> 36×36×2(台)
E34: 37×37×2 | F34: =VLOOKUP(E34,Sheet3!F:G,2,FALSE) -> #N/A | H34: 13×13×3 | I34: 台) | J34: 白) | K34: =E34&"(台)" -> 37×37×2(台)
E35: 38×38×2 | F35: =VLOOKUP(E35,Sheet3!F:G,2,FALSE) -> #N/A | H35: 14×14×3 | I35: 台) | J35: 台) | K35: =E35&"(台)" -> 38×38×2(台)
E36: 39×39×2 | F36: =VLOOKUP(E36,Sheet3!F:G,2,FALSE) -> #N/A | H36: 15×15×3 | I36: 台) | J36: 台) | K36: =E36&"(台)" -> 39×39×2(台)
E37: 45×45×2 | F37: =VLOOKUP(E37,Sheet3!F:G,2,FALSE) -> #N/A | H37: 15×15×3 | I37: 白) | J37: 白) | K37: =E37&"(台)" -> 45×45×2(台)
E38: 5×5×3 | F38: =VLOOKUP(E38,Sheet3!F:G,2,FALSE) -> #N/A | H38: 16×16×3 | I38: 台) | J38: 台) | K38: =E38&"(台)" -> 5×5×3(台)
E39: 6×6×3 | F39: =VLOOKUP(E39,Sheet3!F:G,2,FALSE) -> #N/A | H39: 16×16×3 | I39: 白) | J39: 白) | K39: =E39&"(台)" -> 6×6×3(台)
E40: 7×7×3 | F40: =VLOOKUP(E40,Sheet3!F:G,2,FALSE) -> #N/A | H40: 31×31×3 | J40: 白) | K40: =E40&"(台)" -> 7×7×3(台)
E41: 8×8×3 | F41: =VLOOKUP(E41,Sheet3!F:G,2,FALSE) -> #N/A | H41: 17×17×3 | I41: 台) | J41: 白) | K41: =E41&"(台)" -> 8×8×3(台)
E42: 9×9×3 | F42: =VLOOKUP(E42,Sheet3!F:G,2,FALSE) -> 0 | H42: 35×35×3 | J42: 台)
...

Sheet Sheet3
F4: 10×10×2 | G4: 台) | I4: 6×6×2
F5: 12×12×2 | G5: 台) | I5: 6×6×2 | J5: 白)
F6: 13×13×2 | G6: 台) | I6: 7×7×2
F7: 13×13×2 | I7: 7×7×2 | J7: 白)
F8: 14×14×2 | I8: 8×8×2
F9: 16×16×2 | I9: 8×8×2 | J9: 白)
F10: 18×18×2 | I10: 9×9×2
F11: 14×14×2 | G11: 台) | I11: 9×9×2 | J11: 白)
F12: 20×20×2 | I12: 10×10×2
F13: 31×31×2 | I13: 10×10×2 | J13: 白)
F14: 16×16×2 | G14: 台) | I14: 10×10×2 | J14: 台)
F15: 9×9×3 | I15: 11×11×2
F16: 9×9×3 | I16: 11×11×2 | J16: 白)
F17: 20×20×2 | G17: 台) | I17: 12×12×2
F18: 21×21×2 | G18: 台) | I18: 12×12×2 | J18: 台)
F19: 30×30×2 | G19: 台) | I19: 13×13×2
F20: 9×9×3 | G20: 台) | I20: 13×13×2 | J20: 台)
F21: 16×16×3 | I21: 13×13×2 | J21: 白)
F22: 12×12×3 | G22: 台) | I22: 14×14×2
F23: 13×13×3 | G23: 台) | I23: 14×14×2 | J23: 台)
F24: 14×14×3 | G24: 台) | I24: 14×14×2 | J24: 白)
F25: 15×15×3 | G25: 台) | I25: 15×15×2
F26: 16×16×3 | G26: 台) | I26: 15×15×2 | J26: 白)
F27: 31×31×3 | I27: 16×16×2
F28: 17×17×3 | G28: 台) | I28: 16×16×2 | J28: 台)
F29: 35×35×3 | I29: 17×17×2
F30: 40×40×3 | I30: 17×17×2 | J30: 白)
F31: 8×8×4 | I31: 18×18×2 | J31: 卡)
F32: 10×10×4 | I32: 18×18×2
F33: 7×7×4 | I33: 19×19×2
F34: 12×12×4 | I34: 19×19×2 | J34: 白)
F35: 13×13×4 | I35: 20×20×2
F36: 13×13×4 | I36: 20×20×2 | J36: 卡)
F37: 14×14×4 | I37: 20×20×2 | J37: 台)
F38: 14×14×4 | I38: 21×21×2
F39: 16×16×4 | I39: 21×21×2 | J39: 台)
F40: 16×16×4 | I40: 22×22×2
F41: 17×17×4 | I41: 22×22×2 | J41: 白)
F42: 18×18×3 | G42: 台) | I42: 23×23×2
F43: 21×21×4 | I43: 23×23×2 | J43: 白)
...

Sheet Sheet5

Sheet Sheet6

Sheet Sheet7

Sheet Sheet8

Sheet Sheet9
